Workbook

Sheet NAVODILA
A2: NAVODILA
A4: Aplikacija za pripravo obrazcev v zvezi z graditvijo objektov je pripomoček za pripravo dokumentacije in zahtevkov v skladu z novim Pravilnikom o podrobnejši vsebini dokumentacije in obrazcih, povezanih z graditvijo objektov. Nova verzija obrazcev glede na prejšnjo uvaja nekaj sprememb, opisanih v nadaljevanju.
A6: Za pravilno delovanje navigacijskih in drugih ukaznih gumbov je potrebno ob odpiranju dokumenta omogočiti uporabo makrov. Uporaba makrov je vezana izključno na delovanje navigacijskih gumbov ter za prenašanje podatkov med datotekami. Vse osnovne funkcionalnosti, torej vnos in izpis podatkov, delujejo tudi brez delovanja makrov. Namesto z uporabo navigacijskih gumbov lahko posamezne liste izbirate v spodnji vrstici aplikacije, za tiskanje in pripravo pdf dokumentov pa uporabite ustrezne ukaze iz menija.
A8: DATOTEKE
A10: Priloge so razdeljene v več datotek. Vsaka izmed datotek je pripravljena za posamezno skupino uporabnikov (projektanti, izvajalci, mnenjedajalci, upravni organ) tako, da vključuje vse faze posameznega postopka. Sklop za projektante je dodatno razdeljen glede na zahtevnost nameravane gradnje. Seznam datotek: - projektanti - obrazci za zahtevne in manj zahtevne objekte - projektanti - obrazci za nezahtevne objekte - projektanti - obrazci za spremembo namembnosti - projektanti - manjša rekonstrukcija - projektanti - legalizacije - projektanti - začasni objekti - izvajalci - DZO - mnenjedajalci - projektni pogoji in mnenja - upravni organ - odločbe V nadaljevanju so opisana navodila za uporabo obrazcev izvajalci - DZO.
A12: ZAŠČITA PODATKOV
A14: Vsi listi v datoteki so odklenjeni. Kljub temu priporočamo, da liste zaklenete tako, da na zavihku Pregled na traku v skupini Spremembe izberete Zaščiti list. Namen te osnovne zaščite je preprečiti nenamerno spreminjanje že izpolnjenih polj. OPOZORILO: Podatke lahko vnašate le v rumeno obarvana okenca, vrstice pa lahko dodajate le tam, kjer je to izrecno navedeno, sicer se podatki morda ne bodo prenesli pravilno!
A16: KAZALO VSEBINE
A18: List za vnos podatkov ima v zgornjem delu kazalo celotne vsebine. Vsebina je razporejena v tabelo, ki je razporejena tako kot je sestavljena vloga v posamezni fazi upravnega postopka. Naslovi delujejo kot povezave na posamezne liste.
A20: VNAŠANJE PODATKOV
A22: Nekatere vsebine vnašamo s pomočjo spustnih menijev, pri nekaterih vsebinah pa je potrebno označiti izbiro. Pod posameznimi naslovi so opombe z dodatnimi navodili za izpolnjevanje, stolpec A na listu vnos podatkov je namenjen internim opombam uporabnika.
A24: PRENAŠANJE PODATKOV MED DATOTEKAMI
... A41: NADALJUJ NA VNOS PODATKOV

Sheet VNOS PODATKOV
C1: VSEBINA DATOTEKE:
C2: DOKAZILO O ZANESLJIVOSTI
C3: obarvana polja delujejo kot povezave na ustrezne liste
C4: PRIDOBIVANJE UPORABNEGA DOVOLJENJA
C6: 5A - VODILNA MAPA DZO
C7: 5B - MAPA IZVAJALCA DZO
A11: PROSTOR ZA OPOMBE | C11: VNOS PODATKOV
B13: A | C13: UDELEŽENCI PRI GRADITVI
B14: A1 | C14: INVESTITOR
B15: A1.1 | C15: INVESTITOR
C16: INVESTITOR 1
C17: ime in priimek ali naziv družbe
C18: naslov ali sedež družbe
C19: INVESTITOR 2
C20: ime in priimek ali naziv družbe
C21: naslov ali sedež družbe
C22: INVESTITOR 3
C23: ime in priimek ali naziv družbe
C24: naslov ali sedež družbe
B25: A2 | C25: PROJEKTANT
B26: A2.1 | C26: PROJEKTANT
C27: PODATKI O DRUŽBI
C28: projektant (naziv družbe)
C29: poslovni naslov družbe
C30: odgovorna oseba projektanta
B31: A2.6 | C31: IZDELOVALEC VODILNE MAPE DOKAZILA O ZANESLJIVOSTI
C32: ime in priimek ali naziv družbe
C33: naslov ali sedež družbe
B34: A3 | C34: NADZORNIK
B35: A3.1 | C35: NADZORNIK
C36: imenovanje nadzornika ni obvezno v primeru gradnje nezahtevnega objekta če jo izvaja izvajalec, ki izpolnjuje pogoje za opravljanje dejavnosti gradbeništva (16. člen GZ-1)
C37: imenovan je nadzornik gradnje
C38: PODATKI O DRUŽBI
C39: naziv družbe
C40: poslovni naslov družbe
C41: davčna številka za pravne subjekte
C42: odgovorna oseba nadzornika
C43: VODJA NADZORA
C44: vodja nadzora
C45: strokovna izobrazba
...

Sheet 5A DZO VM
A1: PRILOGA 5A
A2: VODILNA MAPA DOKAZILA O ZANESLJIVOSTI
A3: STRAN 1: PODATKI O OBJEKTU IN DOKAZILU O ZANESLJIVOSTI
A5: ='VNOS PODATKOV'!C103
A6: ='VNOS PODATKOV'!C105 | C6: ='VNOS PODATKOV'!D105
A7: ='VNOS PODATKOV'!C106 | C7: ='VNOS PODATKOV'!D106
A9: ='VNOS PODATKOV'!C76
A10: ='VNOS PODATKOV'!C79 | C10: ='VNOS PODATKOV'!D79
A12: OSNOVNI PODATKI O OBJEKTIH
A13: imenovanje objekta
A14: vrsta gradnje
A15: zahtevnost objekta
A16: klasifikacija po CC-SI
A17: po potrebi dodati rubrike
A19: ='VNOS PODATKOV'!C31
A20: ='VNOS PODATKOV'!C32 | C20: ='VNOS PODATKOV'!D32
A21: ='VNOS PODATKOV'!C33 | C21: ='VNOS PODATKOV'!D33
A22: STRAN 2: PODATKI O UDELEŽENCIH PRI GRADITVI
A24: ='VNOS PODATKOV'!C15
A25: ='VNOS PODATKOV'!C16
A26: ='VNOS PODATKOV'!C17 | C26: ='VNOS PODATKOV'!D17
A27: ='VNOS PODATKOV'!C18 | C27: ='VNOS PODATKOV'!D18
A28: ='VNOS PODATKOV'!C19
A29: ='VNOS PODATKOV'!C20 | C29: ='VNOS PODATKOV'!D20
A30: ='VNOS PODATKOV'!C21 | C30: ='VNOS PODATKOV'!D21
A31: ='VNOS PODATKOV'!C22
A32: ='VNOS PODATKOV'!C23 | C32: ='VNOS PODATKOV'!D23
A33: ='VNOS PODATKOV'!C24 | C33: ='VNOS PODATKOV'!D24
A35: ='VNOS PODATKOV'!C35
A36: ='VNOS PODATKOV'!C39 | C36: ='VNOS PODATKOV'!D39
A37: ='VNOS PODATKOV'!C40 | C37: ='VNOS PODATKOV'!D40
A38: ='VNOS PODATKOV'!C42 | C38: ='VNOS PODATKOV'!D42
A39: ='VNOS PODATKOV'!C44 | C39: ='VNOS PODATKOV'!D44
A40: ='VNOS PODATKOV'!C45 | C40: ='VNOS PODATKOV'!D45
A41: ='VNOS PODATKOV'!C46 | C41: ='VNOS PODATKOV'!D46
A43: ='VNOS PODATKOV'!C47
A44: ='VNOS PODATKOV'!C48 | C44: ='VNOS PODATKOV'!D48 | D44: ='VNOS PODATKOV'!E48 | E44: ='VNOS PODATKOV'!F48 | F44: ='VNOS PODATKOV'!G48
A45: ='VNOS PODATKOV'!C49 | C45: ='VNOS PODATKOV'!D49 | D45: ='VNOS PODATKOV'!E49 | E45: ='VNOS PODATKOV'!F49 | F45: ='VNOS PODATKOV'!G49
A46: ='VNOS PODATKOV'!C50 | C46: ='VNOS PODATKOV'!D50
A47: ='VNOS PODATKOV'!C51 | C47: ='VNOS PODATKOV'!D51
...

Sheet 5B DZO
A1: PRILOGA 5B
A2: DOKAZILO IZVAJALCA
A3: STRAN 1: IZJAVA IZVAJALCA IN VODJE GRADNJE
A4: IZVAJALEC IN VODJA GRADNJE
A5: ='VNOS PODATKOV'!C60 | D5: ='VNOS PODATKOV'!D60:E60
A6: ='VNOS PODATKOV'!C61 | D6: ='VNOS PODATKOV'!D61:E61
A7: ='VNOS PODATKOV'!C63 | D7: ='VNOS PODATKOV'!D63
A8: ='VNOS PODATKOV'!C65 | D8: ='VNOS PODATKOV'!D65:E65
A11: s predloženim dokazilom št. | D11: ='VNOS PODATKOV'!D105
A12: datum izdelave | D12: ='VNOS PODATKOV'!D106
D14: IZJAVLJAVA:
D16: - da so dela v okviru prevzete storitve dokončana; - da je predloženo dokazilo v okviru prevzete storitve izdelano v celoti; - da vgrajeni gradbeni proizvodi, naprave in materiali izpolnjujejo predpise; - da so bili pri gradnji upoštevani ukrepi, s katerimi bodo preprečeni oziroma na najmanjšo mero omejeni negativni vplivi, ki jih utegne povzročiti objekt oziroma njegova uporaba; - da predloženo dokazilo dokazuje, da objekt glede na namen, vrsto, velikost, zmogljivost, predvidene vplive in druge značilnosti, v okviru prevzete storitve izpolnjuje bistvene in druge zahteve in - da so dela izvedena v skladu s projektno dokumentacijo za izvedbo gradnje:
A18: ='VNOS PODATKOV'!C74 | D18: ='VNOS PODATKOV'!D74
A19: ='VNOS PODATKOV'!C75 | D19: ='VNOS PODATKOV'!D75
A20: ='VNOS PODATKOV'!C28 | D20: ='VNOS PODATKOV'!D28
A23: ='VNOS PODATKOV'!C63 | D23: ='VNOS PODATKOV'!D63
A24: podpis odgovorne osebe izvajalca
A25: ='VNOS PODATKOV'!C65 | D25: =IF('VNOS PODATKOV'!D65="","",(CONCATENATE('VNOS PODATKOV'!D65,", ",'VNOS PODATKOV'!D66)))
A26: ='VNOS PODATKOV'!C67 | D26: ='VNOS PODATKOV'!D67
A27: podpis vodje gradnje
A30: STRAN 2: OSTALI UDELEŽENI POSAMZNIKI IZVAJALCA PRI VODENJU GRADNJE, ČE SO BILI DOLOČENI
A32: ime in priimek, identifikacijska številka
A33: obseg vodenja gradnje
A34: po potrebi dodati rubrike
A36: STRAN 2: TABELARIČNO KAZALO DOKAZIL
A37: po potrebi izpustiti ali dodati vrstice
B39: PODATKI O POGODBAH, SKLENJENIH MED INVESTITORJEM IN IZVAJALCEM
B40: tabelarični seznam sklenjenih pogodb z oštevilčenjem, kot si sledijo v mapi s prilogami
A41: zap. št. | B41: pogodba | D41: vrsta del | G41: datum
A42: 1
A43: 2
A44: 3
A45: 4
A46: 5
A48: I. | B48: GRADBENA DELA
B49: tabelarični seznam posameznih dokazil glede gradnje stanovanjskih in nestanovanjskih stavb, gradnje inženirskih objektov cest in železnic z mostovi, predori, objektov oskrbne infrastrukture za tekočine, pline, elektriko, telekomunikacije, drugih inženirskih objektov z vodnimi objekti in drugimi objekti nizke gradnje, z oštevilčenjem, kot si sledijo v prilogah
A50: zap. št. | B50: ime dokazila oz. na kaj se dokazilo nanaša | D50: izdajatelj | F50: št. dokazila | G50: datum
A51: 1
A52: 2
A53: 3
...
